Workbook

Sheet 00_Control
A1: Grayson Swim Site - master control
A2: Private master workbook. Do not publish this workbook to the public GitHub repository.
A4: Setting | B4: Value | C4: Purpose
A5: Workbook version | B5: 3.0 | C5: All-event Grayson consistency build; canonical swimmer IDs reconciled
A6: Build date | B6: 46305 | C6: Current build date
A7: Consistency analysis start | B7: 45292 | C7: Fixed start date requested by user
A8: Progression maximum age | B8: Through age 20 (<21.0 exact age) | C8: Do not plot comparison performances after age 20
A9: Progression population | B9: Male only | C9: Comparison page scope
A10: Exact age denominator | B10: 365.2425 | C10: Days per tropical year approximation
A11: Margin formula | B11: (next-fastest - record) / next-fastest | C11: Percent faster than next-fastest different swimmer
A12: Next-fastest rule | B12: Different swimmer | C12: Own previous record is not an eligible comparator
A13: Joint record rule | B13: 0% vs joint holder | C13: Another joint record holder is the next-fastest different swimmer
A14: Public DOB policy | B14: Do not export DOBs | C14: DOB retained only in private master workbook
A15: Trend selection | B15: Cross-validated parsimonious best fit | C15: Leave-one-meet-out where meet identifiers are available
A16: All-event consistency scope | B16: All Grayson SCM/LCM event-course combinations with a swim since 1 Jan 2024 | C16: Dynamic from SwimCloud all-event history plus audited supplements
A18: Trend model candidates
A19: Model | B19: Horizontal asymptote? | C19: Role
A20: Linear | B20: No | C20: Transparent baseline
A21: Quadratic | B21: No | C21: Captures curvature but can turn unrealistically
A22: Logarithmic | B22: No | C22: Diminishing improvement; no true floor
A23: Asymptotic exponential | B23: Yes | C23: Biologically plausible flattening curve
A24: Stretched exponential | B24: Yes | C24: Flexible asymptotic curve
A25: Smoothing spline | B25: No explicit | C25: Descriptive benchmark; avoid using for extrapolation
A28: Acquisition status
A29: Item | B29: Value | C29: Status
A30: SwimCloud API v6 | B30: 19 profiles / 152 target event calls / 126 non-empty event histories / 2,834 raw swims | C30: Complete
A31: NZSC 2026 all-event supplement source | B31: https://swimdadnz.github.io/NZSC_2026/ | C31: Used only for Grayson meet swims not yet present in SwimCloud at acquisition time.
A32: Grayson canonical selected-event swims | B32: 101 | C32: Complete for eight requested events
A33: Grayson all-event consistency | B33: See included v7 Grayson-only acquisition | C33: Pending additional acquisition

Sheet 01_Swimmers
A1: Swimmers
A2: Canonical swimmer table. Exact DOB is private and is not exported to the website.
A4: SwimmerID | B4: Display Name | C4: Full Name | D4: Sex | E4: DOB | F4: Group | G4: Nation | H4: Club | I4: Public Flag
A5: SW001 | B5: Grayson Coulter | C5: Grayson Coulter | D5: M | E5: 40925 | F5: Grayson | I5: YES
A6: SW002 | B6: Miron Bunakov | C6: Miron Bunakov | D6: M | E6: 40800 | F6: Current age group star | I6: YES
A7: SW003 | B7: Luka Mijatovic | C7: Luka Mijatovic | D7: M | E7: 39925 | F7: Current age group star | I7: YES
A8: SW004 | B8: Lubo Liu-Tchorbadjiyski | C8: Lubo Liu-Tchorbadjiyski | D8: M | E8: 40836 | F8: Current age group star | I8: YES
A9: SW005 | B9: Thomas Heilman | C9: Thomas Heilman | D9: M | E9: 39120 | F9: Current age group star | I9: YES
A10: SW006 | B10: Tajus Juska | C10: Tajus Juska | D10: M | E10: 39830 | F10: Current age group star | I10: YES
A11: SW007 | B11: Laon Kim | C11: Laon Kim | D11: M | E11: 39591 | F11: Current age group star | I11: YES
A12: SW008 | B12: Jacob Whittle | C12: Jacob Whittle | D12: M | E12: 38255 | F12: Historical champion | I12: YES
A13: SW009 | B13: David Popovici | C13: David Popovici | D13: M | E13: 38245 | F13: Historical champion | I13: YES
A14: SW010 | B14: Caeleb Dressel | C14: Caeleb Dressel | D14: M | E14: 35293 | F14: Historical champion | I14: YES
A15: SW011 | B15: Kyle Chalmers | C15: Kyle Chalmers | D15: M | E15: 35971 | F15: Historical champion | I15: YES
A16: SW012 | B16: Flynn Southam | C16: Flynn Southam | D16: M | E16: 38508 | F16: Historical champion | I16: YES
... A22: SW018 | B22: Kristof Milak | C22: Kristof Milak | D22: M | E22: 36576 | F22: Historical champion | I22: YES

Sheet 02_Swimmer_Sources
A1: Swimmer sources
A2: One swimmer can have multiple source profiles. Grayson's two SwimCloud profiles map to one canonical swimmer.
A4: SwimmerID | B4: Display Name | C4: Source | D4: External ID | E4: URL | F4: Active | G4: Notes
A5: SW001 | B5: Grayson Coulter | C5: SwimCloud | D5: 3637780 | E5: https://www.swimcloud.com/swimmer/3637780/ | F5: YES
A6: SW001 | B6: Grayson Coulter | C6: SwimCloud | D6: 3651023 | E6: https://www.swimcloud.com/swimmer/3651023/ | F6: YES
A7: SW002 | B7: Miron Bunakov | C7: SwimCloud | D7: 3360584 | E7: https://www.swimcloud.com/swimmer/3360584/ | F7: YES
A8: SW003 | B8: Luka Mijatovic | C8: SwimCloud | D8: 2415996 | E8: https://www.swimcloud.com/swimmer/2415996/ | F8: YES
A9: SW004 | B9: Lubo Liu-Tchorbadjiyski | C9: SwimCloud | D9: 3102544 | E9: https://www.swimcloud.com/swimmer/3102544/ | F9: YES
A10: SW005 | B10: Thomas Heilman | C10: SwimCloud | D10: 1336401 | E10: https://www.swimcloud.com/swimmer/1336401/ | F10: YES
A11: SW006 | B11: Tajus Juska | C11: SwimCloud | D11: 2116196 | E11: https://www.swimcloud.com/swimmer/2116196/ | F11: YES
A12: SW007 | B12: Laon Kim | C12: SwimCloud | D12: 2829279 | E12: https://www.swimcloud.com/swimmer/2829279/ | F12: YES
A13: SW008 | B13: Jacob Whittle | C13: SwimCloud | D13: 1133535 | E13: https://www.swimcloud.com/swimmer/1133535/ | F13: YES
A14: SW009 | B14: David Popovici | C14: SwimCloud | D14: 1405298 | E14: https://www.swimcloud.com/swimmer/1405298/ | F14: YES
A15: SW010 | B15: Caeleb Dressel | C15: SwimCloud | D15: 2361642 | E15: https://www.swimcloud.com/swimmer/2361642/ | F15: YES
A16: SW011 | B16: Kyle Chalmers | C16: SwimCloud | D16: 419989 | E16: https://www.swimcloud.com/swimmer/419989/ | F16: YES
... A23: SW018 | B23: Kristof Milak | C23: SwimCloud | D23: 508643 | E23: https://www.swimcloud.com/swimmer/508643/ | F23: YES

Sheet 03_Events
A1: Events
A2: Standard LCM/SCM event dimension. Progression Flag identifies the eight requested comparison charts.
A4: EventID | B4: Course | C4: Distance | D4: Stroke | E4: Event | F4: Display Name | G4: Progression Flag | H4: Consistency Flag
A5: LCM_50_BACK | B5: LCM | C5: 50 | D5: Back | E5: 50 Back | F5: 50 Back LCM | G5: NO | H5: YES
A6: LCM_50_BREAST | B6: LCM | C6: 50 | D6: Breast | E6: 50 Breast | F6: 50 Breast LCM | G6: NO | H6: YES
A7: LCM_50_FLY | B7: LCM | C7: 50 | D7: Fly | E7: 50 Fly | F7: 50 Fly LCM | G7: NO | H7: YES
A8: LCM_50_FREE | B8: LCM | C8: 50 | D8: Free | E8: 50 Free | F8: 50 Free LCM | G8: NO | H8: YES
A9: LCM_100_BACK | B9: LCM | C9: 100 | D9: Back | E9: 100 Back | F9: 100 Back LCM | G9: NO | H9: YES
A10: LCM_100_BREAST | B10: LCM | C10: 100 | D10: Breast | E10: 100 Breast | F10: 100 Breast LCM | G10: NO | H10: YES
A11: LCM_100_FLY | B11: LCM | C11: 100 | D11: Fly | E11: 100 Fly | F11: 100 Fly LCM | G11: YES | H11: YES
A12: LCM_100_FREE | B12: LCM | C12: 100 | D12: Free | E12: 100 Free | F12: 100 Free LCM | G12: YES | H12: YES
A13: LCM_100_IM | B13: LCM | C13: 100 | D13: IM | E13: 100 IM | F13: 100 IM LCM | G13: NO | H13: YES
A14: LCM_200_BACK | B14: LCM | C14: 200 | D14: Back | E14: 200 Back | F14: 200 Back LCM | G14: NO | H14: YES
A15: LCM_200_BREAST | B15: LCM | C15: 200 | D15: Breast | E15: 200 Breast | F15: 200 Breast LCM | G15: NO | H15: YES
A16: LCM_200_FLY | B16: LCM | C16: 200 | D16: Fly | E16: 200 Fly | F16: 200 Fly LCM | G16: NO | H16: YES
... A40: SCM_1500_FREE | B40: SCM | C40: 1500 | D40: Free | E40: 1500 Free | F40: 1500 Free SCM | G40: NO | H40: YES

Sheet 04_Swims
A1: Swims
A2: Normalized performance database. One row per legal performance; Grayson's two SwimCloud profiles are merged to one canonical swimmer. Formula helper columns support the consistency analysis.
A4: SwimID | B4: SwimmerID | C4: Display Name | D4: Source | E4: Source Profile ID | F4: Source Race ID | G4: Swim Date | H4: Meet | I4: Meet ID | J4: Session | K4: Round | L4: Round Order | M4: Course | N4: Distance | O4: Stroke | P4: Event | Q4: EventID | R4: Time Seconds | S4: Time Display | T4: Exact Age | U4: Age Year | V4: Relay Lead-off | W4: Legal | X4: Exhibition | Y4: Heat | Z4: Lane | AA4: Place | AB4: Source URL | AC4: Acquisition Batch | AD4: Duplicate Key | AE4: Race Order | AF4: Prior Faster Count | AG4: Top 5 At Time | AH4: Top 10 At Time | AI4: In Consistency Window | AJ4: QC Status
A5: SM000001 | B5: SW010 | C5: Caeleb Dressel | D5: SwimCloud | E5: 2361642 | F5: 88639280 | G5: 37757 | H5: 2003 Bolles School Sharks LC Invite | I5: 251562 | K5: TIM | L5: =IF(K5="FIN",3,IF(OR(K5="SEM",K5="SEMI"),2,IF(OR(K5="PRE",K5="HEAT"),1,IF(V5="YES",4,2)))) | M5: LCM | N5: 100 | O5: Free | P5: 100 Free | Q5: LCM_100_FREE | R5: 104.58 | S5: =IF(R5="","",IF(R5>=60,INT(R5/60)&":"&TEXT(MOD(R5,60),"00.00"),TEXT(R5,"0.00"))) | T5: =IFERROR((G5-INDEX('01_Swimmers'!$E$5:$E$22,MATCH(B5,'01_Swimmers'!$A$5:$A$22,0)))/'00_Control'!$B$10,"") | U5: =IF(T5="","",INT(T5)) | V5: NO | W5: YES | X5: NO | Y5: 1 | Z5: 7 | AA5: 3 | AB5: https://www.swimcloud.com/results/251562/event/50/?id=88639280#time88639280 | AC5: SwimCloud API v6 2026-10-08 | AD5: Caeleb Dressel|2003-05-16|LCM|100|Free|104.58|2003 Bolles School Sharks LC Invite|TIM|False | AE5: =G5+L5/1000+ROW()/1000000000 | AF5: =IF(C5<>"Grayson Coulter","",COUNTIFS($C$5:$C$2991,"Grayson Coulter",$Q$5:$Q$2991,Q5,$AE$5:$AE$2991,"<="&AE5,$R$5:$R$2991,"<"&R5)) | AG5: =IF(OR(C5<>"Grayson Coulter",G5<'00_Control'!$B$7),"",--(AF5<5)) | AH5: =IF(OR(C5<>"Grayson Coulter",G5<'00_Control'!$B$7),"",--(AF5<10)) | AI5: =IF(AND(C5="Grayson Coulter",G5>='00_Control'!$B$7),"YES","NO") | AJ5: OK
A6: SM000002 | B6: SW010 | C6: Caeleb Dressel | D6: SwimCloud | E6: 2361642 | F6: 86946527 | G6: 38492 | H6: 2005 MARLIN MAY MEET | I6: 250113 | K6: TIM | L6: =IF(K6="FIN",3,IF(OR(K6="SEM",K6="SEMI"),2,IF(OR(K6="PRE",K6="HEAT"),1,IF(V6="YES",4,2)))) | M6: LCM | N6: 100 | O6: Free | P6: 100 Free | Q6: LCM_100_FREE | R6: 78.49 | S6: =IF(R6="","",IF(R6>=60,INT(R6/60)&":"&TEXT(MOD(R6,60),"00.00"),TEXT(R6,"0.00"))) | T6: =IFERROR((G6-INDEX('01_Swimmers'!$E$5:$E$22,MATCH(B6,'01_Swimmers'!$A$5:$A$22,0)))/'00_Control'!$B$10,"") | U6: =IF(T6="","",INT(T6)) | V6: NO | W6: YES | X6: NO | Y6: 2 | Z6: 8 | AA6: 1 | AB6: https://www.swimcloud.com/results/250113/event/6/?id=86946527#time86946527 | AC6: SwimCloud API v6 2026-10-08 | AD6: Caeleb Dressel|2005-05-20|LCM|100|Free|78.49|2005 MARLIN MAY MEET|TIM|False | AE6: =G6+L6/1000+ROW()/1000000000 | AF6: =IF(C6<>"Grayson Coulter","",COUNTIFS($C$5:$C$2991,"Grayson Coulter",$Q$5:$Q$2991,Q6,$AE$5:$AE$2991,"<="&AE6,$R$5:$R$2991,"<"&R6)) | AG6: =IF(OR(C6<>"Grayson Coulter",G6<'00_Control'!$B$7),"",--(AF6<5)) | AH6: =IF(OR(C6<>"Grayson Coulter",G6<'00_Control'!$B$7),"",--(AF6<10)) | AI6: =IF(AND(C6="Grayson Coulter",G6>='00_Control'!$B$7),"YES","NO") | AJ6: OK
A7: SM000003 | B7: SW010 | C7: Caeleb Dressel | D7: SwimCloud | E7: 2361642 | F7: 86926540 | G7: 38512 | H7: Daytona Beach Swimming 2005 Su | I7: 250102 | K7: TIM | L7: =IF(K7="FIN",3,IF(OR(K7="SEM",K7="SEMI"),2,IF(OR(K7="PRE",K7="HEAT"),1,IF(V7="YES",4,2)))) | M7: LCM | N7: 100 | O7: Free | P7: 100 Free | Q7: LCM_100_FREE | R7: 81.26 | S7: =IF(R7="","",IF(R7>=60,INT(R7/60)&":"&TEXT(MOD(R7,60),"00.00"),TEXT(R7,"0.00"))) | T7: =IFERROR((G7-INDEX('01_Swimmers'!$E$5:$E$22,MATCH(B7,'01_Swimmers'!$A$5:$A$22,0)))/'00_Control'!$B$10,"") | U7: =IF(T7="","",INT(T7)) | V7: NO | W7: YES | X7: NO | Y7: 1 | Z7: 2 | AA7: 8 | AB7: https://www.swimcloud.com/results/250102/event/112/?id=86926540#time86926540 | AC7: SwimCloud API v6 2026-10-08 | AD7: Caeleb Dressel|2005-06-09|LCM|100|Free|81.26|Daytona Beach Swimming 2005 Su|TIM|False | AE7: =G7+L7/1000+ROW()/1000000000 | AF7: =IF(C7<>"Grayson Coulter","",COUNTIFS($C$5:$C$2991,"Grayson Coulter",$Q$5:$Q$2991,Q7,$AE$5:$AE$2991,"<="&AE7,$R$5:$R$2991,"<"&R7)) | AG7: =IF(OR(C7<>"Grayson Coulter",G7<'00_Control'!$B$7),"",--(AF7<5)) | AH7: =IF(OR(C7<>"Grayson Coulter",G7<'00_Control'!$B$7),"",--(AF7<10)) | AI7: =IF(AND(C7="Grayson Coulter",G7>='00_Control'!$B$7),"YES","NO") | AJ7: OK
A8: SM000004 | B8: SW010 | C8: Caeleb Dressel | D8: SwimCloud | E8: 2361642 | F8: 85685937 | G8: 38836 | H8: Highlander Long Course Invitat | I8: 248680 | K8: TIM | L8: =IF(K8="FIN",3,IF(OR(K8="SEM",K8="SEMI"),2,IF(OR(K8="PRE",K8="HEAT"),1,IF(V8="YES",4,2)))) | M8: LCM | N8: 100 | O8: Free | P8: 100 Free | Q8: LCM_100_FREE | R8: 70.27 | S8: =IF(R8="","",IF(R8>=60,INT(R8/60)&":"&TEXT(MOD(R8,60),"00.00"),TEXT(R8,"0.00"))) | T8: =IFERROR((G8-INDEX('01_Swimmers'!$E$5:$E$22,MATCH(B8,'01_Swimmers'!$A$5:$A$22,0)))/'00_Control'!$B$10,"") | U8: =IF(T8="","",INT(T8)) | V8: NO | W8: YES | X8: NO | Y8: 5 | Z8: 4 | AA8: 2 | AB8: https://www.swimcloud.com/results/248680/event/38/?id=85685937#time85685937 | AC8: SwimCloud API v6 2026-10-08 | AD8: Caeleb Dressel|2006-04-29|LCM|100|Free|70.27|Highlander Long Course Invitat|TIM|False | AE8: =G8+L8/1000+ROW()/1000000000 | AF8: =IF(C8<>"Grayson Coulter","",COUNTIFS($C$5:$C$2991,"Grayson Coulter",$Q$5:$Q$2991,Q8,$AE$5:$AE$2991,"<="&AE8,$R$5:$R$2991,"<"&R8)) | AG8: =IF(OR(C8<>"Grayson Coulter",G8<'00_Control'!$B$7),"",--(AF8<5)) | AH8: =IF(OR(C8<>"Grayson Coulter",G8<'00_Control'!$B$7),"",--(AF8<10)) | AI8: =IF(AND(C8="Grayson Coulter",G8>='00_Control'!$B$7),"YES","NO") | AJ8: OK
A9: SM000005 | B9: SW010 | C9: Caeleb Dressel | D9: SwimCloud | E9: 2361642 | F9: 85654045 | G9: 38857 | H9: 2006 FL Marlin May Meet | I9: 248665 | K9: TIM | L9: =IF(K9="FIN",3,IF(OR(K9="SEM",K9="SEMI"),2,IF(OR(K9="PRE",K9="HEAT"),1,IF(V9="YES",4,2)))) | M9: LCM | N9: 100 | O9: Free | P9: 100 Free | Q9: LCM_100_FREE | R9: 70.59 | S9: =IF(R9="","",IF(R9>=60,INT(R9/60)&":"&TEXT(MOD(R9,60),"00.00"),TEXT(R9,"0.00"))) | T9: =IFERROR((G9-INDEX('01_Swimmers'!$E$5:$E$22,MATCH(B9,'01_Swimmers'!$A$5:$A$22,0)))/'00_Control'!$B$10,"") | U9: =IF(T9="","",INT(T9)) | V9: NO | W9: YES | X9: NO | Y9: 4 | Z9: 4 | AA9: 1 | AB9: https://www.swimcloud.com/results/248665/event/6/?id=85654045#time85654045 | AC9: SwimCloud API v6 2026-10-08 | AD9: Caeleb Dressel|2006-05-20|LCM|100|Free|70.59|2006 FL Marlin May Meet|TIM|False | AE9: =G9+L9/1000+ROW()/1000000000 | AF9: =IF(C9<>"Grayson Coulter","",COUNTIFS($C$5:$C$2991,"Grayson Coulter",$Q$5:$Q$2991,Q9,$AE$5:$AE$2991,"<="&AE9,$R$5:$R$2991,"<"&R9)) | AG9: =IF(OR(C9<>"Grayson Coulter",G9<'00_Control'!$B$7),"",--(AF9<5)) | AH9: =IF(OR(C9<>"Grayson Coulter",G9<'00_Control'!$B$7),"",--(AF9<10)) | AI9: =IF(AND(C9="Grayson Coulter",G9>='00_Control'!$B$7),"YES","NO") | AJ9: OK
A10: SM000006 | B10: SW010 | C10: Caeleb Dressel | D10: SwimCloud | E10: 2361642 | F10: 85608130 | G10: 38878 | H10: 2006 Stonewood Invitational | I10: 248614 | K10: TIM | L10: =IF(K10="FIN",3,IF(OR(K10="SEM",K10="SEMI"),2,IF(OR(K10="PRE",K10="HEAT"),1,IF(V10="YES",4,2)))) | M10: LCM | N10: 100 | O10: Fly | P10: 100 Fly | Q10: LCM_100_FLY | R10: 79.55 | S10: =IF(R10="","",IF(R10>=60,INT(R10/60)&":"&TEXT(MOD(R10,60),"00.00"),TEXT(R10,"0.00"))) | T10: =IFERROR((G10-INDEX('01_Swimmers'!$E$5:$E$22,MATCH(B10,'01_Swimmers'!$A$5:$A$22,0)))/'00_Control'!$B$10,"") | U10: =IF(T10="","",INT(T10)) | V10: NO | W10: YES | X10: NO | Y10: 3 | Z10: 4 | AA10: 1 | AB10: https://www.swimcloud.com/results/248614/event/78/?id=85608130#time85608130 | AC10: SwimCloud API v6 2026-10-08 | AD10: Caeleb Dressel|2006-06-10|LCM|100|Fly|79.55|2006 Stonewood Invitational|TIM|False | AE10: =G10+L10/1000+ROW()/1000000000 | AF10: =IF(C10<>"Grayson Coulter","",COUNTIFS($C$5:$C$2991,"Grayson Coulter",$Q$5:$Q$2991,Q10,$AE$5:$AE$2991,"<="&AE10,$R$5:$R$2991,"<"&R10)) | AG10: =IF(OR(C10<>"Grayson Coulter",G10<'00_Control'!$B$7),"",--(AF10<5)) | AH10: =IF(OR(C10<>"Grayson Coulter",G10<'00_Control'!$B$7),"",--(AF10<10)) | AI10: =IF(AND(C10="Grayson Coulter",G10>='00_Control'!$B$7),"YES","NO") | AJ10: OK
A11: SM000007 | B11: SW010 | C11: Caeleb Dressel | D11: SwimCloud | E11: 2361642 | F11: 85607143 | G11: 38878 | H11: 2006 Stonewood Invitational | I11: 248614 | K11: TIM | L11: =IF(K11="FIN",3,IF(OR(K11="SEM",K11="SEMI"),2,IF(OR(K11="PRE",K11="HEAT"),1,IF(V11="YES",4,2)))) | M11: LCM | N11: 100 | O11: Free | P11: 100 Free | Q11: LCM_100_FREE | R11: 67.97 | S11: =IF(R11="","",IF(R11>=60,INT(R11/60)&":"&TEXT(MOD(R11,60),"00.00"),TEXT(R11,"0.00"))) | T11: =IFERROR((G11-INDEX('01_Swimmers'!$E$5:$E$22,MATCH(B11,'01_Swimmers'!$A$5:$A$22,0)))/'00_Control'!$B$10,"") | U11: =IF(T11="","",INT(T11)) | V11: NO | W11: YES | X11: NO | Y11: 6 | Z11: 4 | AA11: 1 | AB11: https://www.swimcloud.com/results/248614/event/82/?id=85607143#time85607143 | AC11: SwimCloud API v6 2026-10-08 | AD11: Caeleb Dressel|2006-06-10|LCM|100|Free|67.97|2006 Stonewood Invitational|TIM|False | AE11: =G11+L11/1000+ROW()/1000000000 | AF11: =IF(C11<>"Grayson Coulter","",COUNTIFS($C$5:$C$2991,"Grayson Coulter",$Q$5:$Q$2991,Q11,$AE$5:$AE$2991,"<="&AE11,$R$5:$R$2991,"<"&R11)) | AG11: =IF(OR(C11<>"Grayson Coulter",G11<'00_Control'!$B$7),"",--(AF11<5)) | AH11: =IF(OR(C11<>"Grayson Coulter",G11<'00_Control'!$B$7),"",--(AF11<10)) | AI11: =IF(AND(C11="Grayson Coulter",G11>='00_Control'!$B$7),"YES","NO") | AJ11: OK
A12: SM000008 | B12: SW010 | C12: Caeleb Dressel | D12: SwimCloud | E12: 2361642 | F12: 85544054 | G12: 38897 | H12: Speedo Summer Classic LC Invit | I12: 248588 | K12: TIM | L12: =IF(K12="FIN",3,IF(OR(K12="SEM",K12="SEMI"),2,IF(OR(K12="PRE",K12="HEAT"),1,IF(V12="YES",4,2)))) | M12: LCM | N12: 400 | O12: Free | P12: 400 Free | Q12: LCM_400_FREE | R12: 318.65 | S12: =IF(R12="","",IF(R12>=60,INT(R12/60)&":"&TEXT(MOD(R12,60),"00.00"),TEXT(R12,"0.00"))) | T12: =IFERROR((G12-INDEX('01_Swimmers'!$E$5:$E$22,MATCH(B12,'01_Swimmers'!$A$5:$A$22,0)))/'00_Control'!$B$10,"") | U12: =IF(T12="","",INT(T12)) | V12: NO | W12: YES | X12: NO | Y12: 1 | Z12: 6 | AA12: 1 | AB12: https://www.swimcloud.com/results/248588/event/2/?id=85544054#time85544054 | AC12: SwimCloud API v6 2026-10-08 | AD12: Caeleb Dressel|2006-06-29|LCM|400|Free|318.65|Speedo Summer Classic LC Invit|TIM|False | AE12: =G12+L12/1000+ROW()/1000000000 | AF12: =IF(C12<>"Grayson Coulter","",COUNTIFS($C$5:$C$2991,"Grayson Coulter",$Q$5:$Q$2991,Q12,$AE$5:$AE$2991,"<="&AE12,$R$5:$R$2991,"<"&R12)) | AG12: =IF(OR(C12<>"Grayson Coulter",G12<'00_Control'!$B$7),"",--(AF12<5)) | AH12: =IF(OR(C12<>"Grayson Coulter",G12<'00_Control'!$B$7),"",--(AF12<10)) | AI12: =IF(AND(C12="Grayson Coulter",G12>='00_Control'!$B$7),"YES","NO") | AJ12: OK
A13: SM000009 | B13: SW010 | C13: Caeleb Dressel | D13: SwimCloud | E13: 2361642 | F13: 85543634 | G13: 38898 | H13: Speedo Summer Classic LC Invit | I13: 248588 | K13: TIM | L13: =IF(K13="FIN",3,IF(OR(K13="SEM",K13="SEMI"),2,IF(OR(K13="PRE",K13="HEAT"),1,IF(V13="YES",4,2)))) | M13: LCM | N13: 200 | O13: Free | P13: 200 Free | Q13: LCM_200_FREE | R13: 150.46 | S13: =IF(R13="","",IF(R13>=60,INT(R13/60)&":"&TEXT(MOD(R13,60),"00.00"),TEXT(R13,"0.00"))) | T13: =IFERROR((G13-INDEX('01_Swimmers'!$E$5:$E$22,MATCH(B13,'01_Swimmers'!$A$5:$A$22,0)))/'00_Control'!$B$10,"") | U13: =IF(T13="","",INT(T13)) | V13: NO | W13: YES | X13: NO | Y13: 2 | Z13: 4 | AA13: 1 | AB13: https://www.swimcloud.com/results/248588/event/34/?id=85543634#time85543634 | AC13: SwimCloud API v6 2026-10-08 | AD13: Caeleb Dressel|2006-06-30|LCM|200|Free|150.46|Speedo Summer Classic LC Invit|TIM|False | AE13: =G13+L13/1000+ROW()/1000000000 | AF13: =IF(C13<>"Grayson Coulter","",COUNTIFS($C$5:$C$2991,"Grayson Coulter",$Q$5:$Q$2991,Q13,$AE$5:$AE$2991,"<="&AE13,$R$5:$R$2991,"<"&R13)) | AG13: =IF(OR(C13<>"Grayson Coulter",G13<'00_Control'!$B$7),"",--(AF13<5)) | AH13: =IF(OR(C13<>"Grayson Coulter",G13<'00_Control'!$B$7),"",--(AF13<10)) | AI13: =IF(AND(C13="Grayson Coulter",G13>='00_Control'!$B$7),"YES","NO") | AJ13: OK
A14: SM000010 | B14: SW010 | C14: Caeleb Dressel | D14: SwimCloud | E14: 2361642 | F14: 85435502 | G14: 38918 | H14: 2006 LC JO Championships | I14: 248449 | K14: TIM | L14: =IF(K14="FIN",3,IF(OR(K14="SEM",K14="SEMI"),2,IF(OR(K14="PRE",K14="HEAT"),1,IF(V14="YES",4,2)))) | M14: LCM | N14: 400 | O14: Free | P14: 400 Free | Q14: LCM_400_FREE | R14: 316.79 | S14: =IF(R14="","",IF(R14>=60,INT(R14/60)&":"&TEXT(MOD(R14,60),"00.00"),TEXT(R14,"0.00"))) | T14: =IFERROR((G14-INDEX('01_Swimmers'!$E$5:$E$22,MATCH(B14,'01_Swimmers'!$A$5:$A$22,0)))/'00_Control'!$B$10,"") | U14: =IF(T14="","",INT(T14)) | V14: NO | W14: YES | X14: NO | Y14: 1 | Z14: 2 | AA14: 8 | AB14: https://www.swimcloud.com/results/248449/event/2/?id=85435502#time85435502 | AC14: SwimCloud API v6 2026-10-08 | AD14: Caeleb Dressel|2006-07-20|LCM|400|Free|316.79|2006 LC JO Championships|TIM|False | AE14: =G14+L14/1000+ROW()/1000000000 | AF14: =IF(C14<>"Grayson Coulter","",COUNTIFS($C$5:$C$2991,"Grayson Coulter",$Q$5:$Q$2991,Q14,$AE$5:$AE$2991,"<="&AE14,$R$5:$R$2991,"<"&R14)) | AG14: =IF(OR(C14<>"Grayson Coulter",G14<'00_Control'!$B$7),"",--(AF14<5)) | AH14: =IF(OR(C14<>"Grayson Coulter",G14<'00_Control'!$B$7),"",--(AF14<10)) | AI14: =IF(AND(C14="Grayson Coulter",G14>='00_Control'!$B$7),"YES","NO") | AJ14: OK
A15: SM000011 | B15: SW010 | C15: Caeleb Dressel | D15: SwimCloud | E15: 2361642 | F15: 85435532 | G15: 38919 | H15: 2006 LC JO Championships | I15: 248449 | K15: TIM | L15: =IF(K15="FIN",3,IF(OR(K15="SEM",K15="SEMI"),2,IF(OR(K15="PRE",K15="HEAT"),1,IF(V15="YES",4,2)))) | M15: LCM | N15: 200 | O15: Free | P15: 200 Free | Q15: LCM_200_FREE | R15: 147.05 | S15: =IF(R15="","",IF(R15>=60,INT(R15/60)&":"&TEXT(MOD(R15,60),"00.00"),TEXT(R15,"0.00"))) | T15: =IFERROR((G15-INDEX('01_Swimmers'!$E$5:$E$22,MATCH(B15,'01_Swimmers'!$A$5:$A$22,0)))/'00_Control'!$B$10,"") | U15: =IF(T15="","",INT(T15)) | V15: NO | W15: YES | X15: NO | Y15: 5 | Z15: 2 | AA15: 5 | AB15: https://www.swimcloud.com/results/248449/event/18/?id=85435532#time85435532 | AC15: SwimCloud API v6 2026-10-08 | AD15: Caeleb Dressel|2006-07-21|LCM|200|Free|147.05|2006 LC JO Championships|TIM|False | AE15: =G15+L15/1000+ROW()/1000000000 | AF15: =IF(C15<>"Grayson Coulter","",COUNTIFS($C$5:$C$2991,"Grayson Coulter",$Q$5:$Q$2991,Q15,$AE$5:$AE$2991,"<="&AE15,$R$5:$R$2991,"<"&R15)) | AG15: =IF(OR(C15<>"Grayson Coulter",G15<'00_Control'!$B$7),"",--(AF15<5)) | AH15: =IF(OR(C15<>"Grayson Coulter",G15<'00_Control'!$B$7),"",--(AF15<10)) | AI15: =IF(AND(C15="Grayson Coulter",G15>='00_Control'!$B$7),"YES","NO") | AJ15: OK
A16: SM000012 | B16: SW010 | C16: Caeleb Dressel | D16: SwimCloud | E16: 2361642 | F16: 85435649 | G16: 38921 | H16: 2006 LC JO Championships | I16: 248449 | K16: TIM | L16: =IF(K16="FIN",3,IF(OR(K16="SEM",K16="SEMI"),2,IF(OR(K16="PRE",K16="HEAT"),1,IF(V16="YES",4,2)))) | M16: LCM | N16: 100 | O16: Free | P16: 100 Free | Q16: LCM_100_FREE | R16: 66.82 | S16: =IF(R16="","",IF(R16>=60,INT(R16/60)&":"&TEXT(MOD(R16,60),"00.00"),TEXT(R16,"0.00"))) | T16: =IFERROR((G16-INDEX('01_Swimmers'!$E$5:$E$22,MATCH(B16,'01_Swimmers'!$A$5:$A$22,0)))/'00_Control'!$B$10,"") | U16: =IF(T16="","",INT(T16)) | V16: NO | W16: YES | X16: NO | Y16: 5 | Z16: 3 | AA16: 3 | AB16: https://www.swimcloud.com/results/248449/event/84/?id=85435649#time85435649 | AC16: SwimCloud API v6 2026-10-08 | AD16: Caeleb Dressel|2006-07-23|LCM|100|Free|66.82|2006 LC JO Championships|TIM|False | AE16: =G16+L16/1000+ROW()/1000000000 | AF16: =IF(C16<>"Grayson Coulter","",COUNTIFS($C$5:$C$2991,"Grayson Coulter",$Q$5:$Q$2991,Q16,$AE$5:$AE$2991,"<="&AE16,$R$5:$R$2991,"<"&R16)) | AG16: =IF(OR(C16<>"Grayson Coulter",G16<'00_Control'!$B$7),"",--(AF16<5)) | AH16: =IF(OR(C16<>"Grayson Coulter",G16<'00_Control'!$B$7),"",--(AF16<10)) | AI16: =IF(AND(C16="Grayson Coulter",G16>='00_Control'!$B$7),"YES","NO") | AJ16: OK
... A67: SM000063 | B67: SW010 | C67: Caeleb Dressel | D67: SwimCloud | E67: 2361642 | F67: 2503929 | G67: 40949 | H67: USA Swimming Grand Prix - Missouri (18 & Under Times) | I67: 18544 | K67: PRE | L67: =IF(K67="FIN",3,IF(OR(K67="SEM",K67="SEMI"),2,IF(OR(K67="PRE",K67="HEAT"),1,IF(V67="YES",4,2)))) | M67: LCM | N67: 200 | O67: Free | P67: 200 Free | Q67: LCM_200_FREE | R67: 120.5 | S67: =IF(R67="","",IF(R67>=60,INT(R67/60)&":"&TEXT(MOD(R67,60),"00.00"),TEXT(R67,"0.00"))) | T67: =IFERROR((G67-INDEX('01_Swimmers'!$E$5:$E$22,MATCH(B67,'01_Swimmers'!$A$5:$A$22,0)))/'00_Control'!$B$10,"") | U67: =IF(T67="","",INT(T67)) | V67: NO | W67: YES | X67: NO | Y67: 2 | Z67: 1 | AA67: 79 | AB67: https://www.swimcloud.com/results/18544/event/2/?id=2503929#time2503929 | AC67: SwimCloud API v6 2026-10-08 | AD67: Caeleb Dressel|2012-02-10|LCM|200|Free|120.5|USA Swimming Grand Prix - Missouri (18 & Under Times)|PRE|False | AE67: =G67+L67/1000+ROW()/1000000000 | AF67: =IF(C67<>"Grayson Coulter","",COUNTIFS($C$5:$C$2991,"Grayson Coulter",$Q$5:$Q$2991,Q67,$AE$5:$AE$2991,"<="&AE67,$R$5:$R$2991,"<"&R67)) | AG67: =IF(OR(C67<>"Grayson Coulter",G67<'00_Control'!$B$7),"",--(AF67<5)) | AH67: =IF(OR(C67<>"Grayson Coulter",G67<'00_Control'!$B$7),"",--(AF67<10)) | AI67: =IF(AND(C67="Grayson Coulter",G67>='00_Control'!$B$7),"YES","NO") | AJ67: OK
A68: SM000064 | B68: SW010 | C68: Caeleb Dressel | D68: SwimCloud | E68: 2361642 | F68: 2504706 | G68: 40950 | H68: USA Swimming Grand Prix - Missouri (18 & Under Times) | I68: 18544 | K68: TIM | L68: =IF(K68="FIN",3,IF(OR(K68="SEM",K68="SEMI"),2,IF(OR(K68="PRE",K68="HEAT"),1,IF(V68="YES",4,2)))) | M68: LCM | N68: 200 | O68: Free | P68: 200 Free | Q68: LCM_200_FREE | R68: 118.7 | S68: =IF(R68="","",IF(R68>=60,INT(R68/60)&":"&TEXT(MOD(R68,60),"00.00"),TEXT(R68,"0.00"))) | T68: =IFERROR((G68-INDEX('01_Swimmers'!$E$5:$E$22,MATCH(B68,'01_Swimmers'!$A$5:$A$22,0)))/'00_Control'!$B$10,"") | U68: =IF(T68="","",INT(T68)) | V68: YES | W68: YES | X68: NO | Y68: 2 | Z68: 6 | AB68: https://www.swimcloud.com/results/18544/event/22/?id=2504412#time2504412 | AC68: SwimCloud API v6 2026-10-08 | AD68: Caeleb Dressel|2012-02-11|LCM|200|Free|118.7|USA Swimming Grand Prix - Missouri (18 & Under Times)|TIM|True | AE68: =G68+L68/1000+ROW()/1000000000 | AF68: =IF(C68<>"Grayson Coulter","",COUNTIFS($C$5:$C$2991,"Grayson Coulter",$Q$5:$Q$2991,Q68,$AE$5:$AE$2991,"<="&AE68,$R$5:$R$2991,"<"&R68)) | AG68: =IF(OR(C68<>"Grayson Coulter",G68<'00_Control'!$B$7),"",--(AF68<5)) | AH68: =IF(OR(C68<>"Grayson Coulter",G68<'00_Control'!$B$7),"",--(AF68<10)) | AI68: =IF(AND(C68="Grayson Coulter",G68>='00_Control'!$B$7),"YES","NO") | AJ68: OK
A69: SM000065 | B69: SW010 | C69: Caeleb Dressel | D69: SwimCloud | E69: 2361642 | F69: 2502723 | G69: 40951 | H69: USA Swimming Grand Prix - Missouri (18 & Under Times) | I69: 18544 | K69: PRE | L69: =IF(K69="FIN",3,IF(OR(K69="SEM",K69="SEMI"),2,IF(OR(K69="PRE",K69="HEAT"),1,IF(V69="YES",4,2)))) | M69: LCM | N69: 100 | O69: Free | P69: 100 Free | Q69: LCM_100_FREE | R69: 52.54 | S69: =IF(R69="","",IF(R69>=60,INT(R69/60)&":"&TEXT(MOD(R69,60),"00.00"),TEXT(R69,"0.00"))) | T69: =IFERROR((G69-INDEX('01_Swimmers'!$E$5:$E$22,MATCH(B69,'01_Swimmers'!$A$5:$A$22,0)))/'00_Control'!$B$10,"") | U69: =IF(T69="","",INT(T69)) | V69: NO | W69: YES | X69: NO | Y69: 10 | Z69: 6 | AA69: 28 | AB69: https://www.swimcloud.com/results/18544/event/30/?id=2502723#time2502723 | AC69: SwimCloud API v6 2026-10-08 | AD69: Caeleb Dressel|2012-02-12|LCM|100|Free|52.54|USA Swimming Grand Prix - Missouri (18 & Under Times)|PRE|False | AE69: =G69+L69/1000+ROW()/1000000000 | AF69: =IF(C69<>"Grayson Coulter","",COUNTIFS($C$5:$C$2991,"Grayson Coulter",$Q$5:$Q$2991,Q69,$AE$5:$AE$2991,"<="&AE69,$R$5:$R$2991,"<"&R69)) | AG69: =IF(OR(C69<>"Grayson Coulter",G69<'00_Control'!$B$7),"",--(AF69<5)) | AH69: =IF(OR(C69<>"Grayson Coulter",G69<'00_Control'!$B$7),"",--(AF69<10)) | AI69: =IF(AND(C69="Grayson Coulter",G69>='00_Control'!$B$7),"YES","NO") | AJ69: OK
A70: SM000066 | B70: SW010 | C70: Caeleb Dressel | D70: SwimCloud | E70: 2361642 | F70: 2502766 | G70: 40951 | H70: USA Swimming Grand Prix - Missouri (18 & Under Times) | I70: 18544 | K70: FIN | L70: =IF(K70="FIN",3,IF(OR(K70="SEM",K70="SEMI"),2,IF(OR(K70="PRE",K70="HEAT"),1,IF(V70="YES",4,2)))) | M70: LCM | N70: 100 | O70: Free | P70: 100 Free | Q70: LCM_100_FREE | R70: 52.48 | S70: =IF(R70="","",IF(R70>=60,INT(R70/60)&":"&TEXT(MOD(R70,60),"00.00"),TEXT(R70,"0.00"))) | T70: =IFERROR((G70-INDEX('01_Swimmers'!$E$5:$E$22,MATCH(B70,'01_Swimmers'!$A$5:$A$22,0)))/'00_Control'!$B$10,"") | U70: =IF(T70="","",INT(T70)) | V70: NO | W70: YES | X70: NO | Y70: 1 | Z70: 8 | AA70: 22 | AB70: https://www.swimcloud.com/results/18544/event/30/?id=2502766#time2502766 | AC70: SwimCloud API v6 2026-10-08 | AD70: Caeleb Dressel|2012-02-12|LCM|100|Free|52.48|USA Swimming Grand Prix - Missouri (18 & Under Times)|FIN|False | AE70: =G70+L70/1000+ROW()/1000000000 | AF70: =IF(C70<>"Grayson Coulter","",COUNTIFS($C$5:$C$2991,"Grayson Coulter",$Q$5:$Q$2991,Q70,$AE$5:$AE$2991,"<="&AE70,$R$5:$R$2991,"<"&R70)) | AG70: =IF(OR(C70<>"Grayson Coulter",G70<'00_Control'!$B$7),"",--(AF70<5)) | AH70: =IF(OR(C70<>"Grayson Coulter",G70<'00_Control'!$B$7),"",--(AF70<10)) | AI70: =IF(AND(C70="Grayson Coulter",G70>='00_Control'!$B$7),"YES","NO") | AJ70: OK
A71: SM000067 | B71: SW010 | C71: Caeleb Dressel | D71: SwimCloud | E71: 2361642 | F71: 2757659 | G71: 40984 | H71: Speedo Champions Series - Orlando, FL (18 & Under) | I71: 18896 | K71: PRE | L71: =IF(K71="FIN",3,IF(OR(K71="SEM",K71="SEMI"),2,IF(OR(K71="PRE",K71="HEAT"),1,IF(V71="YES",4,2)))) | M71: LCM | N71: 100 | O71: Fly | P71: 100 Fly | Q71: LCM_100_FLY | R71: 59.72 | S71: =IF(R71="","",IF(R71>=60,INT(R71/60)&":"&TEXT(MOD(R71,60),"00.00"),TEXT(R71,"0.00"))) | T71: =IFERROR((G71-INDEX('01_Swimmers'!$E$5:$E$22,MATCH(B71,'01_Swimmers'!$A$5:$A$22,0)))/'00_Control'!$B$10,"") | U71: =IF(T71="","",INT(T71)) | V71: NO | W71: YES | X71: NO | Y71: 20 | Z71: 8 | AA71: 55 | AB71: https://www.swimcloud.com/results/18896/event/12/?id=2757659#time2757659 | AC71: SwimCloud API v6 2026-10-08 | AD71: Caeleb Dressel|2012-03-16|LCM|100|Fly|59.72|Speedo Champions Series - Orlando, FL (18 & Under)|PRE|False | AE71: =G71+L71/1000+ROW()/1000000000 | AF71: =IF(C71<>"Grayson Coulter","",COUNTIFS($C$5:$C$2991,"Grayson Coulter",$Q$5:$Q$2991,Q71,$AE$5:$AE$2991,"<="&AE71,$R$5:$R$2991,"<"&R71)) | AG71: =IF(OR(C71<>"Grayson Coulter",G71<'00_Control'!$B$7),"",--(AF71<5)) | AH71: =IF(OR(C71<>"Grayson Coulter",G71<'00_Control'!$B$7),"",--(AF71<10)) | AI71: =IF(AND(C71="Grayson Coulter",G71>='00_Control'!$B$7),"YES","NO") | AJ71: OK
A72: SM000068 | B72: SW010 | C72: Caeleb Dressel | D72: SwimCloud | E72: 2361642 | F72: 2758506 | G72: 40984 | H72: Speedo Champions Series - Orlando, FL (18 & Under) | I72: 18896 | K72: PRE | L72: =IF(K72="FIN",3,IF(OR(K72="SEM",K72="SEMI"),2,IF(OR(K72="PRE",K72="HEAT"),1,IF(V72="YES",4,2)))) | M72: LCM | N72: 200 | O72: Free | P72: 200 Free | Q72: LCM_200_FREE | R72: 116.65 | S72: =IF(R72="","",IF(R72>=60,INT(R72/60)&":"&TEXT(MOD(R72,60),"00.00"),TEXT(R72,"0.00"))) | T72: =IFERROR((G72-INDEX('01_Swimmers'!$E$5:$E$22,MATCH(B72,'01_Swimmers'!$A$5:$A$22,0)))/'00_Control'!$B$10,"") | U72: =IF(T72="","",INT(T72)) | V72: NO | W72: YES | X72: NO | Y72: 5 | Z72: 5 | AA72: 29 | AB72: https://www.swimcloud.com/results/18896/event/8/?id=2758506#time2758506 | AC72: SwimCloud API v6 2026-10-08 | AD72: Caeleb Dressel|2012-03-16|LCM|200|Free|116.65|Speedo Champions Series - Orlando, FL (18 & Under)|PRE|False | AE72: =G72+L72/1000+ROW()/1000000000 | AF72: =IF(C72<>"Grayson Coulter","",COUNTIFS($C$5:$C$2991,"Grayson Coulter",$Q$5:$Q$2991,Q72,$AE$5:$AE$2991,"<="&AE72,$R$5:$R$2991,"<"&R72)) | AG72: =IF(OR(C72<>"Grayson Coulter",G72<'00_Control'!$B$7),"",--(AF72<5)) | AH72: =IF(OR(C72<>"Grayson Coulter",G72<'00_Control'!$B$7),"",--(AF72<10)) | AI72: =IF(AND(C72="Grayson Coulter",G72>='00_Control'!$B$7),"YES","NO") | AJ72: OK
A73: SM000069 | B73: SW010 | C73: Caeleb Dressel | D73: SwimCloud | E73: 2361642 | F73: 2758582 | G73: 40984 | H73: Speedo Champions Series - Orlando, FL (18 & Under) | I73: 18896 | K73: FIN | L73: =IF(K73="FIN",3,IF(OR(K73="SEM",K73="SEMI"),2,IF(OR(K73="PRE",K73="HEAT"),1,IF(V73="YES",4,2)))) | M73: LCM | N73: 200 | O73: Free | P73: 200 Free | Q73: LCM_200_FREE | R73: 114.88 | S73: =IF(R73="","",IF(R73>=60,INT(R73/60)&":"&TEXT(MOD(R73,60),"00.00"),TEXT(R73,"0.00"))) | T73: =IFERROR((G73-INDEX('01_Swimmers'!$E$5:$E$22,MATCH(B73,'01_Swimmers'!$A$5:$A$22,0)))/'00_Control'!$B$10,"") | U73: =IF(T73="","",INT(T73)) | V73: NO | W73: YES | X73: NO | Y73: 3 | Z73: 2 | AA73: 18 | AB73: https://www.swimcloud.com/results/18896/event/8/?id=2758582#time2758582 | AC73: SwimCloud API v6 2026-10-08 | AD73: Caeleb Dressel|2012-03-16|LCM|200|Free|114.88|Speedo Champions Series - Orlando, FL (18 & Under)|FIN|False | AE73: =G73+L73/1000+ROW()/1000000000 | AF73: =IF(C73<>"Grayson Coulter","",COUNTIFS($C$5:$C$2991,"Grayson Coulter",$Q$5:$Q$2991,Q73,$AE$5:$AE$2991,"<="&AE73,$R$5:$R$2991,"<"&R73)) | AG73: =IF(OR(C73<>"Grayson Coulter",G73<'00_Control'!$B$7),"",--(AF73<5)) | AH73: =IF(OR(C73<>"Grayson Coulter",G73<'00_Control'!$B$7),"",--(AF73<10)) | AI73: =IF(AND(C73="Grayson Coulter",G73>='00_Control'!$B$7),"YES","NO") | AJ73: OK
A74: SM000070 | B74: SW010 | C74: Caeleb Dressel | D74: SwimCloud | E74: 2361642 | F74: 2757894 | G74: 40986 | H74: Speedo Champions Series - Orlando, FL (18 & Under) | I74: 18896 | K74: PRE | L74: =IF(K74="FIN",3,IF(OR(K74="SEM",K74="SEMI"),2,IF(OR(K74="PRE",K74="HEAT"),1,IF(V74="YES",4,2)))) | M74: LCM | N74: 100 | O74: Free | P74: 100 Free | Q74: LCM_100_FREE | R74: 52.65 | S74: =IF(R74="","",IF(R74>=60,INT(R74/60)&":"&TEXT(MOD(R74,60),"00.00"),TEXT(R74,"0.00"))) | T74: =IFERROR((G74-INDEX('01_Swimmers'!$E$5:$E$22,MATCH(B74,'01_Swimmers'!$A$5:$A$22,0)))/'00_Control'!$B$10,"") | U74: =IF(T74="","",INT(T74)) | V74: NO | W74: YES | X74: NO | Y74: 22 | Z74: 5 | AA74: 20 | AB74: https://www.swimcloud.com/results/18896/event/30/?id=2757894#time2757894 | AC74: SwimCloud API v6 2026-10-08 | AD74: Caeleb Dressel|2012-03-18|LCM|100|Free|52.65|Speedo Champions Series - Orlando, FL (18 & Under)|PRE|False | AE74: =G74+L74/1000+ROW()/1000000000 | AF74: =IF(C74<>"Grayson Coulter","",COUNTIFS($C$5:$C$2991,"Grayson Coulter",$Q$5:$Q$2991,Q74,$AE$5:$AE$2991,"<="&AE74,$R$5:$R$2991,"<"&R74)) | AG74: =IF(OR(C74<>"Grayson Coulter",G74<'00_Control'!$B$7),"",--(AF74<5)) | AH74: =IF(OR(C74<>"Grayson Coulter",G74<'00_Control'!$B$7),"",--(AF74<10)) | AI74: =IF(AND(C74="Grayson Coulter",G74>='00_Control'!$B$7),"YES","NO") | AJ74: OK
A75: SM000071 | B75: SW010 | C75: Caeleb Dressel | D75: SwimCloud | E75: 2361642 | F75: 2757959 | G75: 40986 | H75: Speedo Champions Series - Orlando, FL (18 & Under) | I75: 18896 | K75: FIN | L75: =IF(K75="FIN",3,IF(OR(K75="SEM",K75="SEMI"),2,IF(OR(K75="PRE",K75="HEAT"),1,IF(V75="YES",4,2)))) | M75: LCM | N75: 100 | O75: Free | P75: 100 Free | Q75: LCM_100_FREE | R75: 52.1 | S75: =IF(R75="","",IF(R75>=60,INT(R75/60)&":"&TEXT(MOD(R75,60),"00.00"),TEXT(R75,"0.00"))) | T75: =IFERROR((G75-INDEX('01_Swimmers'!$E$5:$E$22,MATCH(B75,'01_Swimmers'!$A$5:$A$22,0)))/'00_Control'!$B$10,"") | U75: =IF(T75="","",INT(T75)) | V75: NO | W75: YES | X75: NO | Y75: 3 | Z75: 5 | AA75: 18 | AB75: https://www.swimcloud.com/results/18896/event/30/?id=2757959#time2757959 | AC75: SwimCloud API v6 2026-10-08 | AD75: Caeleb Dressel|2012-03-18|LCM|100|Free|52.1|Speedo Champions Series - Orlando, FL (18 & Under)|FIN|False | AE75: =G75+L75/1000+ROW()/1000000000 | AF75: =IF(C75<>"Grayson Coulter","",COUNTIFS($C$5:$C$2991,"Grayson Coulter",$Q$5:$Q$2991,Q75,$AE$5:$AE$2991,"<="&AE75,$R$5:$R$2991,"<"&R75)) | AG75: =IF(OR(C75<>"Grayson Coulter",G75<'00_Control'!$B$7),"",--(AF75<5)) | AH75: =IF(OR(C75<>"Grayson Coulter",G75<'00_Control'!$B$7),"",--(AF75<10)) | AI75: =IF(AND(C75="Grayson Coulter",G75>='00_Control'!$B$7),"YES","NO") | AJ75: OK
A76: SM000072 | B76: SW010 | C76: Caeleb Dressel | D76: SwimCloud | E76: 2361642 | F76: 28175934 | G76: 41086 | H76: USA Olympic Team Trials | I76: 149710 | K76: PRE | L76: =IF(K76="FIN",3,IF(OR(K76="SEM",K76="SEMI"),2,IF(OR(K76="PRE",K76="HEAT"),1,IF(V76="YES",4,2)))) | M76: LCM | N76: 200 | O76: Free | P76: 200 Free | Q76: LCM_200_FREE | R76: 115.17 | S76: =IF(R76="","",IF(R76>=60,INT(R76/60)&":"&TEXT(MOD(R76,60),"00.00"),TEXT(R76,"0.00"))) | T76: =IFERROR((G76-INDEX('01_Swimmers'!$E$5:$E$22,MATCH(B76,'01_Swimmers'!$A$5:$A$22,0)))/'00_Control'!$B$10,"") | U76: =IF(T76="","",INT(T76)) | V76: NO | W76: YES | X76: NO | Y76: 6 | Z76: 1 | AA76: 121 | AB76: https://www.swimcloud.com/results/149710/event/7/?id=28175934#time28175934 | AC76: SwimCloud API v6 2026-10-08 | AD76: Caeleb Dressel|2012-06-26|LCM|200|Free|115.17|USA Olympic Team Trials|PRE|False | AE76: =G76+L76/1000+ROW()/1000000000 | AF76: =IF(C76<>"Grayson Coulter","",COUNTIFS($C$5:$C$2991,"Grayson Coulter",$Q$5:$Q$2991,Q76,$AE$5:$AE$2991,"<="&AE76,$R$5:$R$2991,"<"&R76)) | AG76: =IF(OR(C76<>"Grayson Coulter",G76<'00_Control'!$B$7),"",--(AF76<5)) | AH76: =IF(OR(C76<>"Grayson Coulter",G76<'00_Control'!$B$7),"",--(AF76<10)) | AI76: =IF(AND(C76="Grayson Coulter",G76>='00_Control'!$B$7),"YES","NO") | AJ76: OK
A77: SM000073 | B77: SW010 | C77: Caeleb Dressel | D77: SwimCloud | E77: 2361642 | F77: 28175935 | G77: 41088 | H77: USA Olympic Team Trials | I77: 149710 | K77: PRE | L77: =IF(K77="FIN",3,IF(OR(K77="SEM",K77="SEMI"),2,IF(OR(K77="PRE",K77="HEAT"),1,IF(V77="YES",4,2)))) | M77: LCM | N77: 100 | O77: Free | P77: 100 Free | Q77: LCM_100_FREE | R77: 52.21 | S77: =IF(R77="","",IF(R77>=60,INT(R77/60)&":"&TEXT(MOD(R77,60),"00.00"),TEXT(R77,"0.00"))) | T77: =IFERROR((G77-INDEX('01_Swimmers'!$E$5:$E$22,MATCH(B77,'01_Swimmers'!$A$5:$A$22,0)))/'00_Control'!$B$10,"") | U77: =IF(T77="","",INT(T77)) | V77: NO | W77: YES | X77: NO | Y77: 3 | Z77: 4 | AA77: 152 | AB77: https://www.swimcloud.com/results/149710/event/14/?id=28175935#time28175935 | AC77: SwimCloud API v6 2026-10-08 | AD77: Caeleb Dressel|2012-06-28|LCM|100|Free|52.21|USA Olympic Team Trials|PRE|False | AE77: =G77+L77/1000+ROW()/1000000000 | AF77: =IF(C77<>"Grayson Coulter","",COUNTIFS($C$5:$C$2991,"Grayson Coulter",$Q$5:$Q$2991,Q77,$AE$5:$AE$2991,"<="&AE77,$R$5:$R$2991,"<"&R77)) | AG77: =IF(OR(C77<>"Grayson Coulter",G77<'00_Control'!$B$7),"",--(AF77<5)) | AH77: =IF(OR(C77<>"Grayson Coulter",G77<'00_Control'!$B$7),"",--(AF77<10)) | AI77: =IF(AND(C77="Grayson Coulter",G77>='00_Control'!$B$7),"YES","NO") | AJ77: OK
A78: SM000074 | B78: SW010 | C78: Caeleb Dressel | D78: SwimCloud | E78: 2361642 | F78: 28175938 | G78: 41090 | H78: USA Olympic Team Trials | I78: 149710 | K78: PRE | L78: =IF(K78="FIN",3,IF(OR(K78="SEM",K78="SEMI"),2,IF(OR(K78="PRE",K78="HEAT"),1,IF(V78="YES",4,2)))) | M78: LCM | N78: 100 | O78: Fly | P78: 100 Fly | Q78: LCM_100_FLY | R78: 57.21 | S78: =IF(R78="","",IF(R78>=60,INT(R78/60)&":"&TEXT(MOD(R78,60),"00.00"),TEXT(R78,"0.00"))) | T78: =IFERROR((G78-INDEX('01_Swimmers'!$E$5:$E$22,MATCH(B78,'01_Swimmers'!$A$5:$A$22,0)))/'00_Control'!$B$10,"") | U78: =IF(T78="","",INT(T78)) | V78: NO | W78: YES | X78: NO | Y78: 2 | Z78: 8 | AA78: 121 | AB78: https://www.swimcloud.com/results/149710/event/23/?id=28175938#time28175938 | AC78: SwimCloud API v6 2026-10-08 | AD78: Caeleb Dressel|2012-06-30|LCM|100|Fly|57.21|USA Olympic Team Trials|PRE|False | AE78: =G78+L78/1000+ROW()/1000000000 | AF78: =IF(C78<>"Grayson Coulter","",COUNTIFS($C$5:$C$2991,"Grayson Coulter",$Q$5:$Q$2991,Q78,$AE$5:$AE$2991,"<="&AE78,$R$5:$R$2991,"<"&R78)) | AG78: =IF(OR(C78<>"Grayson Coulter",G78<'00_Control'!$B$7),"",--(AF78<5)) | AH78: =IF(OR(C78<>"Grayson Coulter",G78<'00_Control'!$B$7),"",--(AF78<10)) | AI78: =IF(AND(C78="Grayson Coulter",G78>='00_Control'!$B$7),"YES","NO") | AJ78: OK
A79: SM000075 | B79: SW010 | C79: Caeleb Dressel | D79: SwimCloud | E79: 2361642 | F79: 2839981 | G79: 41135 | H79: Speedo Junior National Championships (LCM) | I79: 18977 | K79: PRE | L79: =IF(K79="FIN",3,IF(OR(K79="SEM",K79="SEMI"),2,IF(OR(K79="PRE",K79="HEAT"),1,IF(V79="YES",4,2)))) | M79: LCM | N79: 100 | O79: Free | P79: 100 Free | Q79: LCM_100_FREE | R79: 50.85 | S79: =IF(R79="","",IF(R79>=60,INT(R79/60)&":"&TEXT(MOD(R79,60),"00.00"),TEXT(R79,"0.00"))) | T79: =IFERROR((G79-INDEX('01_Swimmers'!$E$5:$E$22,MATCH(B79,'01_Swimmers'!$A$5:$A$22,0)))/'00_Control'!$B$10,"") | U79: =IF(T79="","",INT(T79)) | V79: NO | W79: YES | X79: NO | Y79: 9 | Z79: 3 | AA79: 2 | AB79: https://www.swimcloud.com/results/18977/event/10/?id=2839981#time2839981 | AC79: SwimCloud API v6 2026-10-08 | AD79: Caeleb Dressel|2012-08-14|LCM|100|Free|50.85|Speedo Junior National Championships (LCM)|PRE|False | AE79: =G79+L79/1000+ROW()/1000000000 | AF79: =IF(C79<>"Grayson Coulter","",COUNTIFS($C$5:$C$2991,"Grayson Coulter",$Q$5:$Q$2991,Q79,$AE$5:$AE$2991,"<="&AE79,$R$5:$R$2991,"<"&R79)) | AG79: =IF(OR(C79<>"Grayson Coulter",G79<'00_Control'!$B$7),"",--(AF79<5)) | AH79: =IF(OR(C79<>"Grayson Coulter",G79<'00_Control'!$B$7),"",--(AF79<10)) | AI79: =IF(AND(C79="Grayson Coulter",G79>='00_Control'!$B$7),"YES","NO") | AJ79: OK
A80: SM000076 | B80: SW010 | C80: Caeleb Dressel | D80: SwimCloud | E80: 2361642 | F80: 2840047 | G80: 41135 | H80: Speedo Junior National Championships (LCM) | I80: 18977 | K80: FIN | L80: =IF(K80="FIN",3,IF(OR(K80="SEM",K80="SEMI"),2,IF(OR(K80="PRE",K80="HEAT"),1,IF(V80="YES",4,2)))) | M80: LCM | N80: 100 | O80: Free | P80: 100 Free | Q80: LCM_100_FREE | R80: 50.96 | S80: =IF(R80="","",IF(R80>=60,INT(R80/60)&":"&TEXT(MOD(R80,60),"00.00"),TEXT(R80,"0.00"))) | T80: =IFERROR((G80-INDEX('01_Swimmers'!$E$5:$E$22,MATCH(B80,'01_Swimmers'!$A$5:$A$22,0)))/'00_Control'!$B$10,"") | U80: =IF(T80="","",INT(T80)) | V80: NO | W80: YES | X80: NO | Y80: 3 | Z80: 5 | AA80: 2 | AB80: https://www.swimcloud.com/results/18977/event/10/?id=2840047#time2840047 | AC80: SwimCloud API v6 2026-10-08 | AD80: Caeleb Dressel|2012-08-14|LCM|100|Free|50.96|Speedo Junior National Championships (LCM)|FIN|False | AE80: =G80+L80/1000+ROW()/1000000000 | AF80: =IF(C80<>"Grayson Coulter","",COUNTIFS($C$5:$C$2991,"Grayson Coulter",$Q$5:$Q$2991,Q80,$AE$5:$AE$2991,"<="&AE80,$R$5:$R$2991,"<"&R80)) | AG80: =IF(OR(C80<>"Grayson Coulter",G80<'00_Control'!$B$7),"",--(AF80<5)) | AH80: =IF(OR(C80<>"Grayson Coulter",G80<'00_Control'!$B$7),"",--(AF80<10)) | AI80: =IF(AND(C80="Grayson Coulter",G80>='00_Control'!$B$7),"YES","NO") | AJ80: OK
... A126: SM000122 | B126: SW010 | C126: Caeleb Dressel | D126: SwimCloud | E126: 2361642 | F126: 6524247 | G126: 42197 | H126: Speedo Champions Series - Orlando | I126: 42623 | K126: FIN | L126: =IF(K126="FIN",3,IF(OR(K126="SEM",K126="SEMI"),2,IF(OR(K126="PRE",K126="HEAT"),1,IF(V126="YES",4,2)))) | M126: LCM | N126: 100 | O126: Free | P126: 100 Free | Q126: LCM_100_FREE | R126: 49.5 | S126: =IF(R126="","",IF(R126>=60,INT(R126/60)&":"&TEXT(MOD(R126,60),"00.00"),TEXT(R126,"0.00"))) | T126: =IFERROR((G126-INDEX('01_Swimmers'!$E$5:$E$22,MATCH(B126,'01_Swimmers'!$A$5:$A$22,0)))/'00_Control'!$B$10,"") | U126: =IF(T126="","",INT(T126)) | V126: NO | W126: YES | X126: NO | Y126: 1 | Z126: 4 | AA126: 1 | AB126: https://www.swimcloud.com/results/42623/event/36/?id=6524247#time6524247 | AC126: SwimCloud API v6 2026-10-08 | AD126: Caeleb Dressel|2015-07-12|LCM|100|Free|49.5|Speedo Champions Series - Orlando|FIN|False | AE126: =G126+L126/1000+ROW()/1000000000 | AF126: =IF(C126<>"Grayson Coulter","",COUNTIFS($C$5:$C$2991,"Grayson Coulter",$Q$5:$Q$2991,Q126,$AE$5:$AE$2991,"<="&AE126,$R$5:$R$2991,"<"&R126)) | AG126: =IF(OR(C126<>"Grayson Coulter",G126<'00_Control'!$B$7),"",--(AF126<5)) | AH126: =IF(OR(C126<>"Grayson Coulter",G126<'00_Control'!$B$7),"",--(AF126<10)) | AI126: =IF(AND(C126="Grayson Coulter",G126>='00_Control'!$B$7),"YES","NO") | AJ126: OK
A127: SM000123 | B127: SW010 | C127: Caeleb Dressel | D127: SwimCloud | E127: 2361642 | F127: 6432228 | G127: 42197 | H127: Southern Zone Senior Championships | I127: 39838 | K127: TIM | L127: =IF(K127="FIN",3,IF(OR(K127="SEM",K127="SEMI"),2,IF(OR(K127="PRE",K127="HEAT"),1,IF(V127="YES",4,2)))) | M127: LCM | N127: 100 | O127: Free | P127: 100 Free | Q127: LCM_100_FREE | R127: 49.64 | S127: =IF(R127="","",IF(R127>=60,INT(R127/60)&":"&TEXT(MOD(R127,60),"00.00"),TEXT(R127,"0.00"))) | T127: =IFERROR((G127-INDEX('01_Swimmers'!$E$5:$E$22,MATCH(B127,'01_Swimmers'!$A$5:$A$22,0)))/'00_Control'!$B$10,"") | U127: =IF(T127="","",INT(T127)) | V127: YES | W127: YES | X127: NO | Y127: 4 | Z127: 3 | AB127: https://www.swimcloud.com/results/39838/event/42/?id=6431280#time6431280 | AC127: SwimCloud API v6 2026-10-08 | AD127: Caeleb Dressel|2015-07-12|LCM|100|Free|49.64|Southern Zone Senior Championships|TIM|True | AE127: =G127+L127/1000+ROW()/1000000000 | AF127: =IF(C127<>"Grayson Coulter","",COUNTIFS($C$5:$C$2991,"Grayson Coulter",$Q$5:$Q$2991,Q127,$AE$5:$AE$2991,"<="&AE127,$R$5:$R$2991,"<"&R127)) | AG127: =IF(OR(C127<>"Grayson Coulter",G127<'00_Control'!$B$7),"",--(AF127<5)) | AH127: =IF(OR(C127<>"Grayson Coulter",G127<'00_Control'!$B$7),"",--(AF127<10)) | AI127: =IF(AND(C127="Grayson Coulter",G127>='00_Control'!$B$7),"YES","NO") | AJ127: OK
A128: SM000124 | B128: SW010 | C128: Caeleb Dressel | D128: SwimCloud | E128: 2361642 | F128: 6526141 | G128: 42197 | H128: Speedo Champions Series - Orlando | I128: 42623 | K128: TIM | L128: =IF(K128="FIN",3,IF(OR(K128="SEM",K128="SEMI"),2,IF(OR(K128="PRE",K128="HEAT"),1,IF(V128="YES",4,2)))) | M128: LCM | N128: 100 | O128: Free | P128: 100 Free | Q128: LCM_100_FREE | R128: 49.64 | S128: =IF(R128="","",IF(R128>=60,INT(R128/60)&":"&TEXT(MOD(R128,60),"00.00"),TEXT(R128,"0.00"))) | T128: =IFERROR((G128-INDEX('01_Swimmers'!$E$5:$E$22,MATCH(B128,'01_Swimmers'!$A$5:$A$22,0)))/'00_Control'!$B$10,"") | U128: =IF(T128="","",INT(T128)) | V128: YES | W128: YES | X128: NO | Y128: 4 | Z128: 3 | AB128: https://www.swimcloud.com/results/42623/event/42/?id=6525193#time6525193 | AC128: SwimCloud API v6 2026-10-08 | AD128: Caeleb Dressel|2015-07-12|LCM|100|Free|49.64|Speedo Champions Series - Orlando|TIM|True | AE128: =G128+L128/1000+ROW()/1000000000 | AF128: =IF(C128<>"Grayson Coulter","",COUNTIFS($C$5:$C$2991,"Grayson Coulter",$Q$5:$Q$2991,Q128,$AE$5:$AE$2991,"<="&AE128,$R$5:$R$2991,"<"&R128)) | AG128: =IF(OR(C128<>"Grayson Coulter",G128<'00_Control'!$B$7),"",--(AF128<5)) | AH128: =IF(OR(C128<>"Grayson Coulter",G128<'00_Control'!$B$7),"",--(AF128<10)) | AI128: =IF(AND(C128="Grayson Coulter",G128>='00_Control'!$B$7),"YES","NO") | AJ128: OK
A129: SM000125 | B129: SW010 | C129: Caeleb Dressel | D129: SwimCloud | E129: 2361642 | F129: 6358941 | G129: 42223 | H129: 2015 Phillips 66 National Championships | I129: 29376 | K129: PRE | L129: =IF(K129="FIN",3,IF(OR(K129="SEM",K129="SEMI"),2,IF(OR(K129="PRE",K129="HEAT"),1,IF(V129="YES",4,2)))) | M129: LCM | N129: 200 | O129: Free | P129: 200 Free | Q129: LCM_200_FREE | R129: 110.22 | S129: =IF(R129="","",IF(R129>=60,INT(R129/60)&":"&TEXT(MOD(R129,60),"00.00"),TEXT(R129,"0.00"))) | T129: =IFERROR((G129-INDEX('01_Swimmers'!$E$5:$E$22,MATCH(B129,'01_Swimmers'!$A$5:$A$22,0)))/'00_Control'!$B$10,"") | U129: =IF(T129="","",INT(T129)) | V129: NO | W129: YES | X129: NO | Y129: 11 | Z129: 6 | AA129: 20 | AB129: https://www.swimcloud.com/results/29376/event/9/?id=6358941#time6358941 | AC129: SwimCloud API v6 2026-10-08 | AD129: Caeleb Dressel|2015-08-07|LCM|200|Free|110.22|2015 Phillips 66 National Championships|PRE|False | AE129: =G129+L129/1000+ROW()/1000000000 | AF129: =IF(C129<>"Grayson Coulter","",COUNTIFS($C$5:$C$2991,"Grayson Coulter",$Q$5:$Q$2991,Q129,$AE$5:$AE$2991,"<="&AE129,$R$5:$R$2991,"<"&R129)) | AG129: =IF(OR(C129<>"Grayson Coulter",G129<'00_Control'!$B$7),"",--(AF129<5)) | AH129: =IF(OR(C129<>"Grayson Coulter",G129<'00_Control'!$B$7),"",--(AF129<10)) | AI129: =IF(AND(C129="Grayson Coulter",G129>='00_Control'!$B$7),"YES","NO") | AJ129: OK
A130: SM000126 | B130: SW010 | C130: Caeleb Dressel | D130: SwimCloud | E130: 2361642 | F130: 6358995 | G130: 42223 | H130: 2015 Phillips 66 National Championships | I130: 29376 | K130: FIN | L130: =IF(K130="FIN",3,IF(OR(K130="SEM",K130="SEMI"),2,IF(OR(K130="PRE",K130="HEAT"),1,IF(V130="YES",4,2)))) | M130: LCM | N130: 200 | O130: Free | P130: 200 Free | Q130: LCM_200_FREE | R130: 111.26 | S130: =IF(R130="","",IF(R130>=60,INT(R130/60)&":"&TEXT(MOD(R130,60),"00.00"),TEXT(R130,"0.00"))) | T130: =IFERROR((G130-INDEX('01_Swimmers'!$E$5:$E$22,MATCH(B130,'01_Swimmers'!$A$5:$A$22,0)))/'00_Control'!$B$10,"") | U130: =IF(T130="","",INT(T130)) | V130: NO | W130: YES | X130: NO | Y130: 1 | Z130: 4 | AA130: 21 | AB130: https://www.swimcloud.com/results/29376/event/9/?id=6358995#time6358995 | AC130: SwimCloud API v6 2026-10-08 | AD130: Caeleb Dressel|2015-08-07|LCM|200|Free|111.26|2015 Phillips 66 National Championships|FIN|False | AE130: =G130+L130/1000+ROW()/1000000000 | AF130: =IF(C130<>"Grayson Coulter","",COUNTIFS($C$5:$C$2991,"Grayson Coulter",$Q$5:$Q$2991,Q130,$AE$5:$AE$2991,"<="&AE130,$R$5:$R$2991,"<"&R130)) | AG130: =IF(OR(C130<>"Grayson Coulter",G130<'00_Control'!$B$7),"",--(AF130<5)) | AH130: =IF(OR(C130<>"Grayson Coulter",G130<'00_Control'!$B$7),"",--(AF130<10)) | AI130: =IF(AND(C130="Grayson Coulter",G130>='00_Control'!$B$7),"YES","NO") | AJ130: OK
A131: SM000127 | B131: SW010 | C131: Caeleb Dressel | D131: SwimCloud | E131: 2361642 | F131: 6357792 | G131: 42225 | H131: 2015 Phillips 66 National Championships | I131: 29376 | K131: PRE | L131: =IF(K131="FIN",3,IF(OR(K131="SEM",K131="SEMI"),2,IF(OR(K131="PRE",K131="HEAT"),1,IF(V131="YES",4,2)))) | M131: LCM | N131: 100 | O131: Free | P131: 100 Free | Q131: LCM_100_FREE | R131: 48.98 | S131: =IF(R131="","",IF(R131>=60,INT(R131/60)&":"&TEXT(MOD(R131,60),"00.00"),TEXT(R131,"0.00"))) | T131: =IFERROR((G131-INDEX('01_Swimmers'!$E$5:$E$22,MATCH(B131,'01_Swimmers'!$A$5:$A$22,0)))/'00_Control'!$B$10,"") | U131: =IF(T131="","",INT(T131)) | V131: NO | W131: YES | X131: NO | Y131: 7 | Z131: 7 | AA131: 1 | AB131: https://www.swimcloud.com/results/29376/event/20/?id=6357792#time6357792 | AC131: SwimCloud API v6 2026-10-08 | AD131: Caeleb Dressel|2015-08-09|LCM|100|Free|48.98|2015 Phillips 66 National Championships|PRE|False | AE131: =G131+L131/1000+ROW()/1000000000 | AF131: =IF(C131<>"Grayson Coulter","",COUNTIFS($C$5:$C$2991,"Grayson Coulter",$Q$5:$Q$2991,Q131,$AE$5:$AE$2991,"<="&AE131,$R$5:$R$2991,"<"&R131)) | AG131: =IF(OR(C131<>"Grayson Coulter",G131<'00_Control'!$B$7),"",--(AF131<5)) | AH131: =IF(OR(C131<>"Grayson Coulter",G131<'00_Control'!$B$7),"",--(AF131<10)) | AI131: =IF(AND(C131="Grayson Coulter",G131>='00_Control'!$B$7),"YES","NO") | AJ131: OK
A132: SM000128 | B132: SW010 | C132: Caeleb Dressel | D132: SwimCloud | E132: 2361642 | F132: 6357857 | G132: 42225 | H132: 2015 Phillips 66 National Championships | I132: 29376 | K132: FIN | L132: =IF(K132="FIN",3,IF(OR(K132="SEM",K132="SEMI"),2,IF(OR(K132="PRE",K132="HEAT"),1,IF(V132="YES",4,2)))) | M132: LCM | N132: 100 | O132: Free | P132: 100 Free | Q132: LCM_100_FREE | R132: 48.78 | S132: =IF(R132="","",IF(R132>=60,INT(R132/60)&":"&TEXT(MOD(R132,60),"00.00"),TEXT(R132,"0.00"))) | T132: =IFERROR((G132-INDEX('01_Swimmers'!$E$5:$E$22,MATCH(B132,'01_Swimmers'!$A$5:$A$22,0)))/'00_Control'!$B$10,"") | U132: =IF(T132="","",INT(T132)) | V132: NO | W132: YES | X132: NO | Y132: 3 | Z132: 4 | AA132: 1 | AB132: https://www.swimcloud.com/results/29376/event/20/?id=6357857#time6357857 | AC132: SwimCloud API v6 2026-10-08 | AD132: Caeleb Dressel|2015-08-09|LCM|100|Free|48.78|2015 Phillips 66 National Championships|FIN|False | AE132: =G132+L132/1000+ROW()/1000000000 | AF132: =IF(C132<>"Grayson Coulter","",COUNTIFS($C$5:$C$2991,"Grayson Coulter",$Q$5:$Q$2991,Q132,$AE$5:$AE$2991,"<="&AE132,$R$5:$R$2991,"<"&R132)) | AG132: =IF(OR(C132<>"Grayson Coulter",G132<'00_Control'!$B$7),"",--(AF132<5)) | AH132: =IF(OR(C132<>"Grayson Coulter",G132<'00_Control'!$B$7),"",--(AF132<10)) | AI132: =IF(AND(C132="Grayson Coulter",G132>='00_Control'!$B$7),"YES","NO") | AJ132: OK
A133: SM000129 | B133: SW010 | C133: Caeleb Dressel | D133: SwimCloud | E133: 2361642 | F133: 6969831 | G133: 42226 | H133: 2015 Phillips 66 National Championships Time Trials | I133: 54165 | K133: TIM | L133: =IF(K133="FIN",3,IF(OR(K133="SEM",K133="SEMI"),2,IF(OR(K133="PRE",K133="HEAT"),1,IF(V133="YES",4,2)))) | M133: LCM | N133: 100 | O133: Fly | P133: 100 Fly | Q133: LCM_100_FLY | R133: 52.99 | S133: =IF(R133="","",IF(R133>=60,INT(R133/60)&":"&TEXT(MOD(R133,60),"00.00"),TEXT(R133,"0.00"))) | T133: =IFERROR((G133-INDEX('01_Swimmers'!$E$5:$E$22,MATCH(B133,'01_Swimmers'!$A$5:$A$22,0)))/'00_Control'!$B$10,"") | U133: =IF(T133="","",INT(T133)) | V133: NO | W133: YES | X133: NO | Y133: 2 | Z133: 5 | AA133: 2 | AB133: https://www.swimcloud.com/results/54165/event/515/?id=6969831#time6969831 | AC133: SwimCloud API v6 2026-10-08 | AD133: Caeleb Dressel|2015-08-10|LCM|100|Fly|52.99|2015 Phillips 66 National Championships Time Trials|TIM|False | AE133: =G133+L133/1000+ROW()/1000000000 | AF133: =IF(C133<>"Grayson Coulter","",COUNTIFS($C$5:$C$2991,"Grayson Coulter",$Q$5:$Q$2991,Q133,$AE$5:$AE$2991,"<="&AE133,$R$5:$R$2991,"<"&R133)) | AG133: =IF(OR(C133<>"Grayson Coulter",G133<'00_Control'!$B$7),"",--(AF133<5)) | AH133: =IF(OR(C133<>"Grayson Coulter",G133<'00_Control'!$B$7),"",--(AF133<10)) | AI133: =IF(AND(C133="Grayson Coulter",G133>='00_Control'!$B$7),"YES","NO") | AJ133: OK
A134: SM000130 | B134: SW010 | C134: Caeleb Dressel | D134: SwimCloud | E134: 2361642 | F134: 7018901 | G134: 42293 | H134: Texas vs. Florida, Indiana - LCM | I134: 55151 | K134: TIM | L134: =IF(K134="FIN",3,IF(OR(K134="SEM",K134="SEMI"),2,IF(OR(K134="PRE",K134="HEAT"),1,IF(V134="YES",4,2)))) | M134: LCM | N134: 100 | O134: Fly | P134: 100 Fly | Q134: LCM_100_FLY | R134: 53.99 | S134: =IF(R134="","",IF(R134>=60,INT(R134/60)&":"&TEXT(MOD(R134,60),"00.00"),TEXT(R134,"0.00"))) | T134: =IFERROR((G134-INDEX('01_Swimmers'!$E$5:$E$22,MATCH(B134,'01_Swimmers'!$A$5:$A$22,0)))/'00_Control'!$B$10,"") | U134: =IF(T134="","",INT(T134)) | V134: NO | W134: YES | X134: NO | Y134: 2 | Z134: 2 | AA134: 1 | AB134: https://www.swimcloud.com/results/55151/event/24/?id=7018901#time7018901 | AC134: SwimCloud API v6 2026-10-08 | AD134: Caeleb Dressel|2015-10-16|LCM|100|Fly|53.99|Texas vs. Florida, Indiana - LCM|TIM|False | AE134: =G134+L134/1000+ROW()/1000000000 | AF134: =IF(C134<>"Grayson Coulter","",COUNTIFS($C$5:$C$2991,"Grayson Coulter",$Q$5:$Q$2991,Q134,$AE$5:$AE$2991,"<="&AE134,$R$5:$R$2991,"<"&R134)) | AG134: =IF(OR(C134<>"Grayson Coulter",G134<'00_Control'!$B$7),"",--(AF134<5)) | AH134: =IF(OR(C134<>"Grayson Coulter",G134<'00_Control'!$B$7),"",--(AF134<10)) | AI134: =IF(AND(C134="Grayson Coulter",G134>='00_Control'!$B$7),"YES","NO") | AJ134: OK
A135: SM000131 | B135: SW010 | C135: Caeleb Dressel | D135: SwimCloud | E135: 2361642 | F135: 7018887 | G135: 42293 | H135: Texas vs. Florida, Indiana - LCM | I135: 55151 | K135: TIM | L135: =IF(K135="FIN",3,IF(OR(K135="SEM",K135="SEMI"),2,IF(OR(K135="PRE",K135="HEAT"),1,IF(V135="YES",4,2)))) | M135: LCM | N135: 100 | O135: Free | P135: 100 Free | Q135: LCM_100_FREE | R135: 50.38 | S135: =IF(R135="","",IF(R135>=60,INT(R135/60)&":"&TEXT(MOD(R135,60),"00.00"),TEXT(R135,"0.00"))) | T135: =IFERROR((G135-INDEX('01_Swimmers'!$E$5:$E$22,MATCH(B135,'01_Swimmers'!$A$5:$A$22,0)))/'00_Control'!$B$10,"") | U135: =IF(T135="","",INT(T135)) | V135: NO | W135: YES | X135: NO | Y135: 2 | Z135: 5 | AA135: 2 | AB135: https://www.swimcloud.com/results/55151/event/16/?id=7018887#time7018887 | AC135: SwimCloud API v6 2026-10-08 | AD135: Caeleb Dressel|2015-10-16|LCM|100|Free|50.38|Texas vs. Florida, Indiana - LCM|TIM|False | AE135: =G135+L135/1000+ROW()/1000000000 | AF135: =IF(C135<>"Grayson Coulter","",COUNTIFS($C$5:$C$2991,"Grayson Coulter",$Q$5:$Q$2991,Q135,$AE$5:$AE$2991,"<="&AE135,$R$5:$R$2991,"<"&R135)) | AG135: =IF(OR(C135<>"Grayson Coulter",G135<'00_Control'!$B$7),"",--(AF135<5)) | AH135: =IF(OR(C135<>"Grayson Coulter",G135<'00_Control'!$B$7),"",--(AF135<10)) | AI135: =IF(AND(C135="Grayson Coulter",G135>='00_Control'!$B$7),"YES","NO") | AJ135: OK
A136: SM000132 | B136: SW010 | C136: Caeleb Dressel | D136: SwimCloud | E136: 2361642 | F136: 7067838 | G136: 42307 | H136: Florida vs. Georgia | I136: 55342 | K136: TIM | L136: =IF(K136="FIN",3,IF(OR(K136="SEM",K136="SEMI"),2,IF(OR(K136="PRE",K136="HEAT"),1,IF(V136="YES",4,2)))) | M136: LCM | N136: 100 | O136: Fly | P136: 100 Fly | Q136: LCM_100_FLY | R136: 55.07 | S136: =IF(R136="","",IF(R136>=60,INT(R136/60)&":"&TEXT(MOD(R136,60),"00.00"),TEXT(R136,"0.00"))) | T136: =IFERROR((G136-INDEX('01_Swimmers'!$E$5:$E$22,MATCH(B136,'01_Swimmers'!$A$5:$A$22,0)))/'00_Control'!$B$10,"") | U136: =IF(T136="","",INT(T136)) | V136: NO | W136: YES | X136: NO | Y136: 1 | Z136: 6 | AA136: 3 | AB136: https://www.swimcloud.com/results/55342/event/28/?id=7067838#time7067838 | AC136: SwimCloud API v6 2026-10-08 | AD136: Caeleb Dressel|2015-10-30|LCM|100|Fly|55.07|Florida vs. Georgia|TIM|False | AE136: =G136+L136/1000+ROW()/1000000000 | AF136: =IF(C136<>"Grayson Coulter","",COUNTIFS($C$5:$C$2991,"Grayson Coulter",$Q$5:$Q$2991,Q136,$AE$5:$AE$2991,"<="&AE136,$R$5:$R$2991,"<"&R136)) | AG136: =IF(OR(C136<>"Grayson Coulter",G136<'00_Control'!$B$7),"",--(AF136<5)) | AH136: =IF(OR(C136<>"Grayson Coulter",G136<'00_Control'!$B$7),"",--(AF136<10)) | AI136: =IF(AND(C136="Grayson Coulter",G136>='00_Control'!$B$7),"YES","NO") | AJ136: OK
...

Sheet 05_Record_Benchmarks
A1: NZ age-group record benchmarks
A2: Current NZ individual age-group records, ages 13-18. Times are stored as display text plus formula-derived numeric seconds.
A4: Record Key | B4: Course | C4: Sex | D4: Age | E4: Event | F4: Record Holder(s) | G4: Holder 1 | H4: Holder 2 | I4: Record Time | J4: Record Seconds | K4: Record Date(s) | L4: Record Basis | M4: Record Source URL | N4: Joint Record? | O4: Top 20 Eligible? | P4: Next Fastest Swimmer | Q4: Next Fastest Time | R4: Next Fastest Seconds | S4: Margin % | T4: Comparator Verified? | U4: Outstanding Rank | V4: Outstanding Key | W4: Review Notes | X4: Source Notes
A5: NZ|SCM|M|13|50 Free | B5: SCM | C5: Male | D5: 13 | E5: 50 Free | F5: Grayson Coulter | G5: Grayson Coulter | I5: 23.61 | J5: =IF(I5="","",IF(ISNUMBER(SEARCH(":",I5)),VALUE(LEFT(I5,SEARCH(":",I5)-1))*60+VALUE(MID(I5,SEARCH(":",I5)+1,99)),VALUE(I5))) | K5: 25.09.25 | L5: Swimming New Zealand Short Course Records by Age - user-supplied PDF | N5: NO | O5: YES | Q5: 24.21 | R5: =IF(Q5="","",IF(ISNUMBER(SEARCH(":",Q5)),VALUE(LEFT(Q5,SEARCH(":",Q5)-1))*60+VALUE(MID(Q5,SEARCH(":",Q5)+1,99)),VALUE(Q5))) | S5: =IF(OR(J5="",R5=""),"",(R5-J5)/R5) | T5: =IF(OR(P5<>"",N5="YES"),"YES","NO") | U5: =IF(AND(O5="YES",T5="YES",S5<>""),COUNTIFS($C$5:$C$424,C5,$S$5:$S$424,">"&S5)+COUNTIFS($C$5:C5,C5,$S$5:S5,S5),"") | V5: =IF(U5="","",C5&"|"&U5) | X5: Next-fastest time supplied in user workbook; swimmer name not yet supplied.
A6: NZ|SCM|M|13|100 Free | B6: SCM | C6: Male | D6: 13 | E6: 100 Free | F6: Grayson Coulter | G6: Grayson Coulter | I6: 50.58 | J6: =IF(I6="","",IF(ISNUMBER(SEARCH(":",I6)),VALUE(LEFT(I6,SEARCH(":",I6)-1))*60+VALUE(MID(I6,SEARCH(":",I6)+1,99)),VALUE(I6))) | K6: 22.09.25 | L6: Swimming New Zealand Short Course Records by Age - user-supplied PDF | N6: NO | O6: YES | P6: Hayden Church | Q6: 53.40 | R6: =IF(Q6="","",IF(ISNUMBER(SEARCH(":",Q6)),VALUE(LEFT(Q6,SEARCH(":",Q6)-1))*60+VALUE(MID(Q6,SEARCH(":",Q6)+1,99)),VALUE(Q6))) | S6: =IF(OR(J6="",R6=""),"",(R6-J6)/R6) | T6: =IF(OR(P6<>"",N6="YES"),"YES","NO") | U6: =IF(AND(O6="YES",T6="YES",S6<>""),COUNTIFS($C$5:$C$424,C6,$S$5:$S$424,">"&S6)+COUNTIFS($C$5:C6,C6,$S$5:S6,S6),"") | V6: =IF(U6="","",C6&"|"&U6) | X6: Next-fastest time supplied in user workbook; swimmer name not yet supplied.
